Workbook

Sheet README
B1: Desert Financial ALM Command Center: financial workbook
B2: Hypothetical concept built from public data. Not affiliated with or endorsed by Desert Financial Credit Union.
B4: Purpose | D4: Data contract for the ALM Command Center build prompt (section 6): every tab the app reads, with real public figures where they exist and a documented ALM model where they do not.
B5: As-of date | D5: June 30, 2026 (latest NCUA 5300 call report). Market data through Sept 29, 2026 (rate-drift chip).
B6: Units | D6: Dollars in thousands. Rates and ratios as decimals (5.75% = 0.0575). Dates as ISO text (YYYY-MM-DD). Long (tidy) tables: one row per period and item.
B7: Provenance | D7: public = NCUA call report, Treasury, FOMC, press releases; audited = DFCU annual reports; modeled = this workbook's ALM model or a documented derivation; hypothetical = illustrative targets, limits, plans and placeholders.
B8: Colors | D8: Blue numbers = hardcoded data or inputs. Black = formulas on the same sheet. Green = formulas that pull from another sheet. Yellow fill = live levers in meta (capital target, watch thresholds, NEV Test thresholds, MBL parameters) that drive limit status, NEV Test class and the MBL cap. Model assumptions in the assumptions tab document the Python model; changing them there does not rerun it.
B9: Model | D9: Monthly cash-flow ALM model in Python (model/ folder; run build_all.py then build_workbook.py). Constant balance sheet NII for 24 months; instantaneous NEV with a bootstrapped Treasury zero curve; 20 scenarios.
B10: Data Health | D10: The checks tab reruns the ten validation checks from the build prompt plus extra reconciliations with live formulas.
B12: Key results (live)
B13: Data status | C13: =checks!$D$74 -> Validated | D13: Validation result from the checks tab
B14: Total assets ($K) | C14: =summary!$C$39 -> 9887845 | D14: June 30, 2026 call report
B15: Net worth ratio | C15: =summary!$C$43 -> 0.12095821 | D15: Four-quarter-average method; reported 12.1%
B16: Loan-to-share | C16: =summary!$C$42 -> 0.59910569 | D16: Industry 82.9% aggregate, 69% median (Q2 2026)
B17: AOCI loss / net worth | C17: =summary!$C$45 -> 0.21848783 | D17: Before the Q3 2026 rate rise
B18: Base Year 1 NII ($K) | C18: =summary!$F$8 -> 327538.5 | D18: Constant balance sheet, rates flat at the June 30 curve; excludes giveback
B19: Year 1 NII change, +300bp | C19: =summary!$H$11 -> 0.02788835 | D19: Asset-sensitive in Year 1 (HELOCs at prime, cash); money market repricing and migration offset
B20: Year 1 NII change, -300bp | C20: =summary!$H$5 -> -0.11032574 | D20: Largest earnings risk is falling rates
B21: NEV ratio, base (internal) | C21: =summary!$O$8 -> 0.1717611 | D21: Includes non-maturity deposit franchise value
B22: NEV change, +300bp (internal) | C22: =summary!$P$11 -> -0.10680273
B23: NCUA NEV Test post-shock ratio | C23: =summary!$O$24 -> 0.040512636 | D23: Standardized share values (approximation); 4% = High threshold
B24: NCUA NEV Test class | C24: =summary!$C$60 -> Moderate | D24: Low > 7% and < 40%; High < 4% or > 65%
B25: Q3 2026 actual move: NEV change | C25: =summary!$P$20 -> -0.034791767 | D25: June 30 to Sept 29 curve (10-year +82bp); rate-drift estimate
B26: AFS fair value change since June 30 ($K) | C26: =summary!$C$61 -> -78226.457 | D26: Rate-drift estimate at the Sept 29, 2026 curve (flows through AOCI)
B27: AOCI loss / net worth after Q3 move | C27: =summary!$C$63 -> 0.28582991 | D27: Estimate; Q3 call report will confirm
B28: MBL cap utilization | C28: =summary!$C$55 -> 0.71693602 | D28: 1.75 x min(net worth, 7% of assets)
B29: Junior-lien home equity / loans | C29: =summary!$C$54 -> 0.39680795 | D29: Policy maximum 45% (hypothetical)
B31: Tab index
B32: Tab | C32: Contract | D32: What it holds
B33: summary | C33: extra | D33: Scenario results (NII, EaR, NEV), repricing gap summary, key metrics, liquidity survival: all formulas
B34: checks | C34: extra | D34: Data Health: the ten section 6 checks plus reconciliations to the call report
B35: meta | C35: R | D35: Settings: as-of date, units, NWR method, capital target, thresholds, disclaimer
B36: balance_sheet | C36: R | D36: Audited year-ends 2020-2025, March 31, 2026 (partial call report), June 30, 2026 detail with yields, WAL, duration, convexity
B37: income_statement | C37: R | D37: Audited FY2020-FY2025, H1 2026 call report, quarterly 2025-2026 (modeled allocation); Member Giveback as its own category
B38: income_statement_totals | C38: extra | D38: Reported totals used by the income identity checks
B39: loans | C39: R | D39: 14 products at June 30, 2026: balances and counts tie to the call report; yields, prepayment, credit and behavior modeled
B40: deposits | C40: R | D40: 13 products and tiers: betas, lags, decay, insured share, certificate rollover
B41: cert_maturities | C41: O | D41: Certificate and IRA certificate maturities by month (60 months)
B42: investments | C42: R | D42: Security groups: book, market, yield, duration, convexity, WAL (AFS ties to call report)
B43: securities_detail | C43: extra | D43: Instrument-level securities with fair values in +300, -300 and Q3-actual
...

Sheet summary
A1: Summary: scenario results, repricing gap, key metrics and liquidity survival (live formulas)
A2: All cells below are formulas over the data tabs. Green = cross-sheet links; black = same-sheet formulas. $ thousands; ratios as decimals.
A3: A. Scenario results (NII: 24-month constant balance sheet; NEV: instantaneous)
A4: scenario_key | B4: scenario_label | C4: type | D4: sort_order | E4: nev_applicable | F4: nii_y1 | G4: nii_y2 | H4: ear_y1 | I4: ear_y2 | J4: net_income_y1 | K4: assets_fv | L4: liabilities_fv | M4: off_balance_fv | N4: nev | O4: nev_ratio | P4: nev_sensitivity
A5: shock_m300 | B5: -300bp shock | C5: shock | D5: 1 | E5: y | F5: =SUMIFS(nii_simulation!$E:$E,nii_simulation!$A:$A,$A5,nii_simulation!$B:$B,"<=12") -> 291402.57 | G5: =SUMIFS(nii_simulation!$E:$E,nii_simulation!$A:$A,$A5,nii_simulation!$B:$B,">12") -> 290452.06 | H5: =F5/F$8-1 -> -0.11032574 | I5: =G5/G$8-1 -> -0.14289624 | J5: =SUMIFS(nii_simulation!$G:$G,nii_simulation!$A:$A,$A5,nii_simulation!$B:$B,"<=12") -> 110261.19 | K5: =IF($E5="y",SUMIFS(nev!$E:$E,nev!$A:$A,$A5,nev!$C:$C,"asset"),"") -> 10416466 | L5: =IF($E5="y",SUMIFS(nev!$E:$E,nev!$A:$A,$A5,nev!$C:$C,"liability"),"") -> 8690955.6 | M5: =IF($E5="y",SUMIFS(nev!$E:$E,nev!$A:$A,$A5,nev!$C:$C,"off_balance"),"") -> 2700 | N5: =IF($E5="y",K5-L5+M5,"") -> 1728210.7 | O5: =IF($E5="y",N5/K5,"") -> 0.16591142 | P5: =IF($E5="y",N5/N$8-1,"") -> 0.044138066
A6: shock_m200 | B6: -200bp shock | C6: shock | D6: 2 | E6: y | F6: =SUMIFS(nii_simulation!$E:$E,nii_simulation!$A:$A,$A6,nii_simulation!$B:$B,"<=12") -> 304033.39 | G6: =SUMIFS(nii_simulation!$E:$E,nii_simulation!$A:$A,$A6,nii_simulation!$B:$B,">12") -> 309019.44 | H6: =F6/F$8-1 -> -0.071762892 | I6: =G6/G$8-1 -> -0.088105173 | J6: =SUMIFS(nii_simulation!$G:$G,nii_simulation!$A:$A,$A6,nii_simulation!$B:$B,"<=12") -> 121272.01 | K6: =IF($E6="y",SUMIFS(nev!$E:$E,nev!$A:$A,$A6,nev!$C:$C,"asset"),"") -> 10151662 | L6: =IF($E6="y",SUMIFS(nev!$E:$E,nev!$A:$A,$A6,nev!$C:$C,"liability"),"") -> 8429216.3 | M6: =IF($E6="y",SUMIFS(nev!$E:$E,nev!$A:$A,$A6,nev!$C:$C,"off_balance"),"") -> 1800 | N6: =IF($E6="y",K6-L6+M6,"") -> 1724245.8 | O6: =IF($E6="y",N6/K6,"") -> 0.16984862 | P6: =IF($E6="y",N6/N$8-1,"") -> 0.041742625
A7: shock_m100 | B7: -100bp shock | C7: shock | D7: 3 | E7: y | F7: =SUMIFS(nii_simulation!$E:$E,nii_simulation!$A:$A,$A7,nii_simulation!$B:$B,"<=12") -> 316744.65 | G7: =SUMIFS(nii_simulation!$E:$E,nii_simulation!$A:$A,$A7,nii_simulation!$B:$B,">12") -> 325888.47 | H7: =F7/F$8-1 -> -0.032954427 | I7: =G7/G$8-1 -> -0.03832585 | J7: =SUMIFS(nii_simulation!$G:$G,nii_simulation!$A:$A,$A7,nii_simulation!$B:$B,"<=12") -> 132363.27 | K7: =IF($E7="y",SUMIFS(nev!$E:$E,nev!$A:$A,$A7,nev!$C:$C,"asset"),"") -> 9896730.2 | L7: =IF($E7="y",SUMIFS(nev!$E:$E,nev!$A:$A,$A7,nev!$C:$C,"liability"),"") -> 8192917.4 | M7: =IF($E7="y",SUMIFS(nev!$E:$E,nev!$A:$A,$A7,nev!$C:$C,"off_balance"),"") -> 900 | N7: =IF($E7="y",K7-L7+M7,"") -> 1704712.8 | O7: =IF($E7="y",N7/K7,"") -> 0.1722501 | P7: =IF($E7="y",N7/N$8-1,"") -> 0.029941277
A8: base | B8: Base (flat rates) | C8: shock | D8: 4 | E8: y | F8: =SUMIFS(nii_simulation!$E:$E,nii_simulation!$A:$A,$A8,nii_simulation!$B:$B,"<=12") -> 327538.5 | G8: =SUMIFS(nii_simulation!$E:$E,nii_simulation!$A:$A,$A8,nii_simulation!$B:$B,">12") -> 338876.19 | H8: =F8/F$8-1 -> 0 | I8: =G8/G$8-1 -> 0 | J8: =SUMIFS(nii_simulation!$G:$G,nii_simulation!$A:$A,$A8,nii_simulation!$B:$B,"<=12") -> 141537.11 | K8: =IF($E8="y",SUMIFS(nev!$E:$E,nev!$A:$A,$A8,nev!$C:$C,"asset"),"") -> 9636380.4 | L8: =IF($E8="y",SUMIFS(nev!$E:$E,nev!$A:$A,$A8,nev!$C:$C,"liability"),"") -> 7981225.1 | M8: =IF($E8="y",SUMIFS(nev!$E:$E,nev!$A:$A,$A8,nev!$C:$C,"off_balance"),"") -> 0 | N8: =IF($E8="y",K8-L8+M8,"") -> 1655155.3 | O8: =IF($E8="y",N8/K8,"") -> 0.1717611 | P8: =IF($E8="y",N8/N$8-1,"") -> 0
A9: shock_p100 | B9: +100bp shock | C9: shock | D9: 5 | E9: y | F9: =SUMIFS(nii_simulation!$E:$E,nii_simulation!$A:$A,$A9,nii_simulation!$B:$B,"<=12") -> 332046.54 | G9: =SUMIFS(nii_simulation!$E:$E,nii_simulation!$A:$A,$A9,nii_simulation!$B:$B,">12") -> 342032.37 | H9: =F9/F$8-1 -> 0.01376341 | I9: =G9/G$8-1 -> 0.0093136604 | J9: =SUMIFS(nii_simulation!$G:$G,nii_simulation!$A:$A,$A9,nii_simulation!$B:$B,"<=12") -> 144425.16 | K9: =IF($E9="y",SUMIFS(nev!$E:$E,nev!$A:$A,$A9,nev!$C:$C,"asset"),"") -> 9392467.8 | L9: =IF($E9="y",SUMIFS(nev!$E:$E,nev!$A:$A,$A9,nev!$C:$C,"liability"),"") -> 7795467.9 | M9: =IF($E9="y",SUMIFS(nev!$E:$E,nev!$A:$A,$A9,nev!$C:$C,"off_balance"),"") -> -1440 | N9: =IF($E9="y",K9-L9+M9,"") -> 1595559.9 | O9: =IF($E9="y",N9/K9,"") -> 0.16987654 | P9: =IF($E9="y",N9/N$8-1,"") -> -0.036005947
A10: shock_p200 | B10: +200bp shock | C10: shock | D10: 6 | E10: y | F10: =SUMIFS(nii_simulation!$E:$E,nii_simulation!$A:$A,$A10,nii_simulation!$B:$B,"<=12") -> 334873.41 | G10: =SUMIFS(nii_simulation!$E:$E,nii_simulation!$A:$A,$A10,nii_simulation!$B:$B,">12") -> 341860.89 | H10: =F10/F$8-1 -> 0.022394068 | I10: =G10/G$8-1 -> 0.0088076496 | J10: =SUMIFS(nii_simulation!$G:$G,nii_simulation!$A:$A,$A10,nii_simulation!$B:$B,"<=12") -> 145632.03 | K10: =IF($E10="y",SUMIFS(nev!$E:$E,nev!$A:$A,$A10,nev!$C:$C,"asset"),"") -> 9160585.4 | L10: =IF($E10="y",SUMIFS(nev!$E:$E,nev!$A:$A,$A10,nev!$C:$C,"liability"),"") -> 7624316.8 | M10: =IF($E10="y",SUMIFS(nev!$E:$E,nev!$A:$A,$A10,nev!$C:$C,"off_balance"),"") -> -2880 | N10: =IF($E10="y",K10-L10+M10,"") -> 1533388.7 | O10: =IF($E10="y",N10/K10,"") -> 0.16738981 | P10: =IF($E10="y",N10/N$8-1,"") -> -0.073568106
A11: shock_p300 | B11: +300bp shock | C11: shock | D11: 7 | E11: y | F11: =SUMIFS(nii_simulation!$E:$E,nii_simulation!$A:$A,$A11,nii_simulation!$B:$B,"<=12") -> 336673 | G11: =SUMIFS(nii_simulation!$E:$E,nii_simulation!$A:$A,$A11,nii_simulation!$B:$B,">12") -> 339925.47 | H11: =F11/F$8-1 -> 0.02788835 | I11: =G11/G$8-1 -> 0.0030963551 | J11: =SUMIFS(nii_simulation!$G:$G,nii_simulation!$A:$A,$A11,nii_simulation!$B:$B,"<=12") -> 146621.62 | K11: =IF($E11="y",SUMIFS(nev!$E:$E,nev!$A:$A,$A11,nev!$C:$C,"asset"),"") -> 8948733.3 | L11: =IF($E11="y",SUMIFS(nev!$E:$E,nev!$A:$A,$A11,nev!$C:$C,"liability"),"") -> 7466033.1 | M11: =IF($E11="y",SUMIFS(nev!$E:$E,nev!$A:$A,$A11,nev!$C:$C,"off_balance"),"") -> -4320 | N11: =IF($E11="y",K11-L11+M11,"") -> 1478380.2 | O11: =IF($E11="y",N11/K11,"") -> 0.16520553 | P11: =IF($E11="y",N11/N$8-1,"") -> -0.10680273
A12: shock_p400 | B12: +400bp shock | C12: shock | D12: 8 | E12: y | F12: =SUMIFS(nii_simulation!$E:$E,nii_simulation!$A:$A,$A12,nii_simulation!$B:$B,"<=12") -> 337181.83 | G12: =SUMIFS(nii_simulation!$E:$E,nii_simulation!$A:$A,$A12,nii_simulation!$B:$B,">12") -> 335695.32 | H12: =F12/F$8-1 -> 0.029441821 | I12: =G12/G$8-1 -> -0.0093865261 | J12: =SUMIFS(nii_simulation!$G:$G,nii_simulation!$A:$A,$A12,nii_simulation!$B:$B,"<=12") -> 147130.44 | K12: =IF($E12="y",SUMIFS(nev!$E:$E,nev!$A:$A,$A12,nev!$C:$C,"asset"),"") -> 8752158.5 | L12: =IF($E12="y",SUMIFS(nev!$E:$E,nev!$A:$A,$A12,nev!$C:$C,"liability"),"") -> 7319145.7 | M12: =IF($E12="y",SUMIFS(nev!$E:$E,nev!$A:$A,$A12,nev!$C:$C,"off_balance"),"") -> -5760 | N12: =IF($E12="y",K12-L12+M12,"") -> 1427252.8 | O12: =IF($E12="y",N12/K12,"") -> 0.16307438 | P12: =IF($E12="y",N12/N$8-1,"") -> -0.13769251
A13: ramp_m200 | B13: -200bp ramp (12 mo) | C13: ramp | D13: 9 | E13: n | F13: =SUMIFS(nii_simulation!$E:$E,nii_simulation!$A:$A,$A13,nii_simulation!$B:$B,"<=12") -> 314725.68 | G13: =SUMIFS(nii_simulation!$E:$E,nii_simulation!$A:$A,$A13,nii_simulation!$B:$B,">12") -> 314702.03 | H13: =F13/F$8-1 -> -0.039118513 | I13: =G13/G$8-1 -> -0.07133626 | J13: =SUMIFS(nii_simulation!$G:$G,nii_simulation!$A:$A,$A13,nii_simulation!$B:$B,"<=12") -> 130209.3 | K13: =IF($E13="y",SUMIFS(nev!$E:$E,nev!$A:$A,$A13,nev!$C:$C,"asset"),"") | L13: =IF($E13="y",SUMIFS(nev!$E:$E,nev!$A:$A,$A13,nev!$C:$C,"liability"),"") | M13: =IF($E13="y",SUMIFS(nev!$E:$E,nev!$A:$A,$A13,nev!$C:$C,"off_balance"),"") | N13: =IF($E13="y",K13-L13+M13,"") | O13: =IF($E13="y",N13/K13,"") | P13: =IF($E13="y",N13/N$8-1,"")
A14: ramp_m100 | B14: -100bp ramp (12 mo) | C14: ramp | D14: 10 | E14: n | F14: =SUMIFS(nii_simulation!$E:$E,nii_simulation!$A:$A,$A14,nii_simulation!$B:$B,"<=12") -> 321189.64 | G14: =SUMIFS(nii_simulation!$E:$E,nii_simulation!$A:$A,$A14,nii_simulation!$B:$B,">12") -> 327956.04 | H14: =F14/F$8-1 -> -0.019383529 | I14: =G14/G$8-1 -> -0.032224598 | J14: =SUMIFS(nii_simulation!$G:$G,nii_simulation!$A:$A,$A14,nii_simulation!$B:$B,"<=12") -> 135930.76 | K14: =IF($E14="y",SUMIFS(nev!$E:$E,nev!$A:$A,$A14,nev!$C:$C,"asset"),"") | L14: =IF($E14="y",SUMIFS(nev!$E:$E,nev!$A:$A,$A14,nev!$C:$C,"liability"),"") | M14: =IF($E14="y",SUMIFS(nev!$E:$E,nev!$A:$A,$A14,nev!$C:$C,"off_balance"),"") | N14: =IF($E14="y",K14-L14+M14,"") | O14: =IF($E14="y",N14/K14,"") | P14: =IF($E14="y",N14/N$8-1,"")
A15: ramp_p100 | B15: +100bp ramp (12 mo) | C15: ramp | D15: 11 | E15: n | F15: =SUMIFS(nii_simulation!$E:$E,nii_simulation!$A:$A,$A15,nii_simulation!$B:$B,"<=12") -> 330947.12 | G15: =SUMIFS(nii_simulation!$E:$E,nii_simulation!$A:$A,$A15,nii_simulation!$B:$B,">12") -> 340381.65 | H15: =F15/F$8-1 -> 0.010406796 | I15: =G15/G$8-1 -> 0.0044425097 | J15: =SUMIFS(nii_simulation!$G:$G,nii_simulation!$A:$A,$A15,nii_simulation!$B:$B,"<=12") -> 144203.24 | K15: =IF($E15="y",SUMIFS(nev!$E:$E,nev!$A:$A,$A15,nev!$C:$C,"asset"),"") | L15: =IF($E15="y",SUMIFS(nev!$E:$E,nev!$A:$A,$A15,nev!$C:$C,"liability"),"") | M15: =IF($E15="y",SUMIFS(nev!$E:$E,nev!$A:$A,$A15,nev!$C:$C,"off_balance"),"") | N15: =IF($E15="y",K15-L15+M15,"") | O15: =IF($E15="y",N15/K15,"") | P15: =IF($E15="y",N15/N$8-1,"")
A16: ramp_p200 | B16: +200bp ramp (12 mo) | C16: ramp | D16: 12 | E16: n | F16: =SUMIFS(nii_simulation!$E:$E,nii_simulation!$A:$A,$A16,nii_simulation!$B:$B,"<=12") -> 333715.69 | G16: =SUMIFS(nii_simulation!$E:$E,nii_simulation!$A:$A,$A16,nii_simulation!$B:$B,">12") -> 338983.83 | H16: =F16/F$8-1 -> 0.018859432 | I16: =G16/G$8-1 -> 0.00031763386 | J16: =SUMIFS(nii_simulation!$G:$G,nii_simulation!$A:$A,$A16,nii_simulation!$B:$B,"<=12") -> 146229.31 | K16: =IF($E16="y",SUMIFS(nev!$E:$E,nev!$A:$A,$A16,nev!$C:$C,"asset"),"") | L16: =IF($E16="y",SUMIFS(nev!$E:$E,nev!$A:$A,$A16,nev!$C:$C,"liability"),"") | M16: =IF($E16="y",SUMIFS(nev!$E:$E,nev!$A:$A,$A16,nev!$C:$C,"off_balance"),"") | N16: =IF($E16="y",K16-L16+M16,"") | O16: =IF($E16="y",N16/K16,"") | P16: =IF($E16="y",N16/N$8-1,"")
... A23: recession_cuts | B23: Recession with cuts | C23: narrative | D23: 19 | E23: n | F23: =SUMIFS(nii_simulation!$E:$E,nii_simulation!$A:$A,$A23,nii_simulation!$B:$B,"<=12") -> 315228.97 | G23: =SUMIFS(nii_simulation!$E:$E,nii_simulation!$A:$A,$A23,nii_simulation!$B:$B,">12") -> 319005 | H23: =F23/F$8-1 -> -0.037581928 | I23: =G23/G$8-1 -> -0.058638483 | J23: =SUMIFS(nii_simulation!$G:$G,nii_simulation!$A:$A,$A23,nii_simulation!$B:$B,"<=12") -> 95518.932 | K23: =IF($E23="y",SUMIFS(nev!$E:$E,nev!$A:$A,$A23,nev!$C:$C,"asset"),"") | L23: =IF($E23="y",SUMIFS(nev!$E:$E,nev!$A:$A,$A23,nev!$C:$C,"liability"),"") | M23: =IF($E23="y",SUMIFS(nev!$E:$E,nev!$A:$A,$A23,nev!$C:$C,"off_balance"),"") | N23: =IF($E23="y",K23-L23+M23,"") | O23: =IF($E23="y",N23/K23,"") | P23: =IF($E23="y",N23/N$8-1,"")
A24: ncua_nev_test | B24: NCUA NEV Test (+300, standardized NMS) | C24: supervisory | D24: 20 | E24: y | F24: =SUMIFS(nii_simulation!$E:$E,nii_simulation!$A:$A,$A24,nii_simulation!$B:$B,"<=12") -> 336673 | G24: =SUMIFS(nii_simulation!$E:$E,nii_simulation!$A:$A,$A24,nii_simulation!$B:$B,">12") -> 339925.47 | H24: =F24/F$8-1 -> 0.02788835 | I24: =G24/G$8-1 -> 0.0030963551 | J24: =SUMIFS(nii_simulation!$G:$G,nii_simulation!$A:$A,$A24,nii_simulation!$B:$B,"<=12") -> 146621.62 | K24: =IF($E24="y",SUMIFS(nev!$E:$E,nev!$A:$A,$A24,nev!$C:$C,"asset"),"") -> 8948733.3 | L24: =IF($E24="y",SUMIFS(nev!$E:$E,nev!$A:$A,$A24,nev!$C:$C,"liability"),"") -> 8581876.5 | M24: =IF($E24="y",SUMIFS(nev!$E:$E,nev!$A:$A,$A24,nev!$C:$C,"off_balance"),"") -> -4320 | N24: =IF($E24="y",K24-L24+M24,"") -> 362536.77 | O24: =IF($E24="y",N24/K24,"") -> 0.040512636 | P24: =N24/SUMIFS(nev_test!$C:$C,nev_test!$A:$A,meta!$B$3,nev_test!$B:$B,"ncua_test")-1 -> -0.50337472
A26: B. Repricing gap, June 30, 2026 (NMD beta-weighted hybrid)
A27: bucket | B27: assets | C27: liabilities | D27: equity | E27: gap | F27: cumulative_gap | G27: cumulative_gap_pct_assets
A28: 0_3m | B28: =SUMIFS(repricing_gap!$D:$D,repricing_gap!$A:$A,meta!$B$3,repricing_gap!$B:$B,$A28,repricing_gap!$C:$C,"asset") -> 2751903.5 | C28: =SUMIFS(repricing_gap!$D:$D,repricing_gap!$A:$A,meta!$B$3,repricing_gap!$B:$B,$A28,repricing_gap!$C:$C,"liability") -> 2230363.4 | D28: =SUMIFS(repricing_gap!$D:$D,repricing_gap!$A:$A,meta!$B$3,repricing_gap!$B:$B,$A28,repricing_gap!$C:$C,"equity") -> 0 | E28: =B28-C28-D28 -> 521540.08 | F28: =E28 -> 521540.08 | G28: =F28/SUM($B$28:$B$34) -> 0.052745576
A29: 3_12m | B29: =SUMIFS(repricing_gap!$D:$D,repricing_gap!$A:$A,meta!$B$3,repricing_gap!$B:$B,$A29,repricing_gap!$C:$C,"asset") -> 847849.95 | C29: =SUMIFS(repricing_gap!$D:$D,repricing_gap!$A:$A,meta!$B$3,repricing_gap!$B:$B,$A29,repricing_gap!$C:$C,"liability") -> 1853615.7 | D29: =SUMIFS(repricing_gap!$D:$D,repricing_gap!$A:$A,meta!$B$3,repricing_gap!$B:$B,$A29,repricing_gap!$C:$C,"equity") -> 0 | E29: =B29-C29-D29 -> -1005765.8 | F29: =F28+E29 -> -484225.72 | G29: =F29/SUM($B$28:$B$34) -> -0.048971816
A30: 1_3y | B30: =SUMIFS(repricing_gap!$D:$D,repricing_gap!$A:$A,meta!$B$3,repricing_gap!$B:$B,$A30,repricing_gap!$C:$C,"asset") -> 2132570.2 | C30: =SUMIFS(repricing_gap!$D:$D,repricing_gap!$A:$A,meta!$B$3,repricing_gap!$B:$B,$A30,repricing_gap!$C:$C,"liability") -> 1753396.9 | D30: =SUMIFS(repricing_gap!$D:$D,repricing_gap!$A:$A,meta!$B$3,repricing_gap!$B:$B,$A30,repricing_gap!$C:$C,"equity") -> 0 | E30: =B30-C30-D30 -> 379173.29 | F30: =F29+E30 -> -105052.44 | G30: =F30/SUM($B$28:$B$34) -> -0.010624402
A31: 3_5y | B31: =SUMIFS(repricing_gap!$D:$D,repricing_gap!$A:$A,meta!$B$3,repricing_gap!$B:$B,$A31,repricing_gap!$C:$C,"asset") -> 1542013.5 | C31: =SUMIFS(repricing_gap!$D:$D,repricing_gap!$A:$A,meta!$B$3,repricing_gap!$B:$B,$A31,repricing_gap!$C:$C,"liability") -> 984960.76 | D31: =SUMIFS(repricing_gap!$D:$D,repricing_gap!$A:$A,meta!$B$3,repricing_gap!$B:$B,$A31,repricing_gap!$C:$C,"equity") -> 0 | E31: =B31-C31-D31 -> 557052.76 | F31: =F30+E31 -> 452000.33 | G31: =F31/SUM($B$28:$B$34) -> 0.045712724
A32: 5_10y | B32: =SUMIFS(repricing_gap!$D:$D,repricing_gap!$A:$A,meta!$B$3,repricing_gap!$B:$B,$A32,repricing_gap!$C:$C,"asset") -> 1122748 | C32: =SUMIFS(repricing_gap!$D:$D,repricing_gap!$A:$A,meta!$B$3,repricing_gap!$B:$B,$A32,repricing_gap!$C:$C,"liability") -> 1190866.1 | D32: =SUMIFS(repricing_gap!$D:$D,repricing_gap!$A:$A,meta!$B$3,repricing_gap!$B:$B,$A32,repricing_gap!$C:$C,"equity") -> 0 | E32: =B32-C32-D32 -> -68118.112 | F32: =F31+E32 -> 383882.22 | G32: =F32/SUM($B$28:$B$34) -> 0.038823648
A33: 10y_plus | B33: =SUMIFS(repricing_gap!$D:$D,repricing_gap!$A:$A,meta!$B$3,repricing_gap!$B:$B,$A33,repricing_gap!$C:$C,"asset") -> 871798.21 | C33: =SUMIFS(repricing_gap!$D:$D,repricing_gap!$A:$A,meta!$B$3,repricing_gap!$B:$B,$A33,repricing_gap!$C:$C,"liability") -> 842397.35 | D33: =SUMIFS(repricing_gap!$D:$D,repricing_gap!$A:$A,meta!$B$3,repricing_gap!$B:$B,$A33,repricing_gap!$C:$C,"equity") -> 0 | E33: =B33-C33-D33 -> 29400.862 | F33: =F32+E33 -> 413283.08 | G33: =F33/SUM($B$28:$B$34) -> 0.041797083
A34: nonrate | B34: =SUMIFS(repricing_gap!$D:$D,repricing_gap!$A:$A,meta!$B$3,repricing_gap!$B:$B,$A34,repricing_gap!$C:$C,"asset") -> 618961.62 | C34: =SUMIFS(repricing_gap!$D:$D,repricing_gap!$A:$A,meta!$B$3,repricing_gap!$B:$B,$A34,repricing_gap!$C:$C,"liability") -> 124418.2 | D34: =SUMIFS(repricing_gap!$D:$D,repricing_gap!$A:$A,meta!$B$3,repricing_gap!$B:$B,$A34,repricing_gap!$C:$C,"equity") -> 907826.51 | E34: =B34-C34-D34 -> -413283.08 | F34: =F33+E34 -> -1.1070399e-05 | G34: =F34/SUM($B$28:$B$34) -> -1.1195967e-12
A35: total | B35: =SUM(B28:B34) -> 9887845 | C35: =SUM(C28:C34) -> 8980018.5 | D35: =SUM(D28:D34) -> 907826.51 | E35: =SUM(E28:E34) -> -1.1070399e-05
A37: C. Key metrics, June 30, 2026
A38: metric_key | B38: label | C38: value | D38: formula / source
A39: total_assets | B39: Total assets ($K) | C39: =history!$B$24 -> 9887845 | D39: history
A40: loans | B40: Loans ($K) | C40: =history!$C$24 -> 5305440.5 | D40: history
A41: shares | B41: Shares ($K) | C41: =history!$D$24 -> 8855600.3 | D41: history
A42: lts | B42: Loan-to-share | C42: =history!$O$24 -> 0.59910569 | D42: history
A43: nwr | B43: Net worth ratio (4-quarter average method) | C43: =history!$S$24 -> 0.12095821 | D43: history
A44: nwr_quarter_end | B44: Net worth ratio (quarter-end assets) | C44: =history!$U$24/history!$B$24 -> 0.11748041 | D44: history
A45: aoci_pct_nw | B45: AOCI loss as % of net worth | C45: =-history!$R$24/history!$U$24 -> 0.21848783 | D45: history
A46: roa | B46: ROA, year to date (annualized) | C46: =history!$J$24 -> 0.011233332 | D46: history
A47: pre_giveback_roa | B47: Pre-giveback ROA, YTD | C47: =history!$W$24 -> 0.01451493 | D47: history
A48: nim | B48: NIM, YTD (ex-giveback) | C48: =history!$K$24 -> 0.031919747 | D48: history
...

Sheet checks
A1: Data Health: validation checks (section 6) and additional reconciliations
A2: Every result is a live formula. PASS / FAIL / WARN; tolerance shown per check.
A4: check_id | B4: check | C4: item | D4: value_a | E4: value_b | F4: difference | G4: tolerance | H4: result
A5: 1 | B5: Balance sheet: assets = liabilities + equity (0.1%) | C5: 2020-12-31 | D5: =SUMIFS(balance_sheet!$E:$E,balance_sheet!$A:$A,"2020-12-31",balance_sheet!$B:$B,"asset") -> 6637949.8 | E5: =SUMIFS(balance_sheet!$E:$E,balance_sheet!$A:$A,"2020-12-31",balance_sheet!$B:$B,"liability")+SUMIFS(balance_sheet!$E:$E,balance_sheet!$A:$A,"2020-12-31",balance_sheet!$B:$B,"equity") -> 6637949.8 | F5: =ROUND(D5-E5,2) -> 0 | G5: 0.001 | H5: =IF(ABS(F5)<=G5*ABS(D5),"PASS","FAIL") -> PASS
A6: 1 | B6: Balance sheet: assets = liabilities + equity (0.1%) | C6: 2021-12-31 | D6: =SUMIFS(balance_sheet!$E:$E,balance_sheet!$A:$A,"2021-12-31",balance_sheet!$B:$B,"asset") -> 8206373.3 | E6: =SUMIFS(balance_sheet!$E:$E,balance_sheet!$A:$A,"2021-12-31",balance_sheet!$B:$B,"liability")+SUMIFS(balance_sheet!$E:$E,balance_sheet!$A:$A,"2021-12-31",balance_sheet!$B:$B,"equity") -> 8206373.3 | F6: =ROUND(D6-E6,2) -> 0 | G6: 0.001 | H6: =IF(ABS(F6)<=G6*ABS(D6),"PASS","FAIL") -> PASS
A7: 1 | B7: Balance sheet: assets = liabilities + equity (0.1%) | C7: 2022-12-31 | D7: =SUMIFS(balance_sheet!$E:$E,balance_sheet!$A:$A,"2022-12-31",balance_sheet!$B:$B,"asset") -> 8192281.9 | E7: =SUMIFS(balance_sheet!$E:$E,balance_sheet!$A:$A,"2022-12-31",balance_sheet!$B:$B,"liability")+SUMIFS(balance_sheet!$E:$E,balance_sheet!$A:$A,"2022-12-31",balance_sheet!$B:$B,"equity") -> 8192281.9 | F7: =ROUND(D7-E7,2) -> 0 | G7: 0.001 | H7: =IF(ABS(F7)<=G7*ABS(D7),"PASS","FAIL") -> PASS
A8: 1 | B8: Balance sheet: assets = liabilities + equity (0.1%) | C8: 2023-12-31 | D8: =SUMIFS(balance_sheet!$E:$E,balance_sheet!$A:$A,"2023-12-31",balance_sheet!$B:$B,"asset") -> 8710563.8 | E8: =SUMIFS(balance_sheet!$E:$E,balance_sheet!$A:$A,"2023-12-31",balance_sheet!$B:$B,"liability")+SUMIFS(balance_sheet!$E:$E,balance_sheet!$A:$A,"2023-12-31",balance_sheet!$B:$B,"equity") -> 8710563.8 | F8: =ROUND(D8-E8,2) -> 0 | G8: 0.001 | H8: =IF(ABS(F8)<=G8*ABS(D8),"PASS","FAIL") -> PASS
A9: 1 | B9: Balance sheet: assets = liabilities + equity (0.1%) | C9: 2024-12-31 | D9: =SUMIFS(balance_sheet!$E:$E,balance_sheet!$A:$A,"2024-12-31",balance_sheet!$B:$B,"asset") -> 8783626.8 | E9: =SUMIFS(balance_sheet!$E:$E,balance_sheet!$A:$A,"2024-12-31",balance_sheet!$B:$B,"liability")+SUMIFS(balance_sheet!$E:$E,balance_sheet!$A:$A,"2024-12-31",balance_sheet!$B:$B,"equity") -> 8783626.8 | F9: =ROUND(D9-E9,2) -> 0 | G9: 0.001 | H9: =IF(ABS(F9)<=G9*ABS(D9),"PASS","FAIL") -> PASS
A10: 1 | B10: Balance sheet: assets = liabilities + equity (0.1%) | C10: 2025-12-31 | D10: =SUMIFS(balance_sheet!$E:$E,balance_sheet!$A:$A,"2025-12-31",balance_sheet!$B:$B,"asset") -> 9535159.3 | E10: =SUMIFS(balance_sheet!$E:$E,balance_sheet!$A:$A,"2025-12-31",balance_sheet!$B:$B,"liability")+SUMIFS(balance_sheet!$E:$E,balance_sheet!$A:$A,"2025-12-31",balance_sheet!$B:$B,"equity") -> 9535159.3 | F10: =ROUND(D10-E10,2) -> 0 | G10: 0.001 | H10: =IF(ABS(F10)<=G10*ABS(D10),"PASS","FAIL") -> PASS
A11: 1 | B11: Balance sheet: assets = liabilities + equity (0.1%) | C11: 2026-03-31 | D11: =SUMIFS(balance_sheet!$E:$E,balance_sheet!$A:$A,"2026-03-31",balance_sheet!$B:$B,"asset") -> 9791191.4 | E11: =SUMIFS(balance_sheet!$E:$E,balance_sheet!$A:$A,"2026-03-31",balance_sheet!$B:$B,"liability")+SUMIFS(balance_sheet!$E:$E,balance_sheet!$A:$A,"2026-03-31",balance_sheet!$B:$B,"equity") -> 9791191.4 | F11: =ROUND(D11-E11,2) -> 0 | G11: 0.001 | H11: =IF(ABS(F11)<=G11*ABS(D11),"PASS","FAIL") -> PASS
A12: 1 | B12: Balance sheet: assets = liabilities + equity (0.1%) | C12: 2026-06-30 | D12: =SUMIFS(balance_sheet!$E:$E,balance_sheet!$A:$A,"2026-06-30",balance_sheet!$B:$B,"asset") -> 9887845 | E12: =SUMIFS(balance_sheet!$E:$E,balance_sheet!$A:$A,"2026-06-30",balance_sheet!$B:$B,"liability")+SUMIFS(balance_sheet!$E:$E,balance_sheet!$A:$A,"2026-06-30",balance_sheet!$B:$B,"equity") -> 9887845 | F12: =ROUND(D12-E12,2) -> 0 | G12: 0.001 | H12: =IF(ABS(F12)<=G12*ABS(D12),"PASS","FAIL") -> PASS
A13: 2 | B13: Loan products sum to balance sheet loans (0.1%) | C13: 2026-06-30 | D13: =SUMIFS(loans!$D:$D,loans!$A:$A,meta!$B$3) -> 5305440.5 | E13: =SUMIFS(balance_sheet!$E:$E,balance_sheet!$A:$A,meta!$B$3,balance_sheet!$C:$C,"loans") -> 5305440.5 | F13: =D13-E13 -> 0 | G13: 0.001 | H13: =IF(ABS(F13)<=G13*ABS(E13),"PASS","FAIL") -> PASS
A14: 2 | B14: Deposit products sum to balance sheet shares (0.1%) | C14: 2026-06-30 | D14: =SUMIFS(deposits!$E:$E,deposits!$A:$A,meta!$B$3) -> 8855600.3 | E14: =SUMIFS(balance_sheet!$E:$E,balance_sheet!$A:$A,meta!$B$3,balance_sheet!$C:$C,"shares") -> 8855600.3 | F14: =D14-E14 -> 0 | G14: 0.001 | H14: =IF(ABS(F14)<=G14*ABS(E14),"PASS","FAIL") -> PASS
A15: 3 | B15: Repricing gap: asset buckets incl. nonrate = total assets | C15: 2026-06-30 | D15: =SUMIFS(repricing_gap!$D:$D,repricing_gap!$A:$A,meta!$B$3,repricing_gap!$C:$C,"asset") -> 9887845 | E15: =SUMIFS(balance_sheet!$E:$E,balance_sheet!$A:$A,meta!$B$3,balance_sheet!$B:$B,"asset") -> 9887845 | F15: =D15-E15 -> 0 | G15: 0.001 | H15: =IF(ABS(F15)<=G15*ABS(E15),"PASS","FAIL") -> PASS
A16: 3 | B16: Repricing gap: liability + equity buckets = liabilities + equity | C16: 2026-06-30 | D16: =SUMIFS(repricing_gap!$D:$D,repricing_gap!$A:$A,meta!$B$3,repricing_gap!$C:$C,"liability")+SUMIFS(repricing_gap!$D:$D,repricing_gap!$A:$A,meta!$B$3,repricing_gap!$C:$C,"equity") -> 9887845 | E16: =SUMIFS(balance_sheet!$E:$E,balance_sheet!$A:$A,meta!$B$3,balance_sheet!$B:$B,"liability")+SUMIFS(balance_sheet!$E:$E,balance_sheet!$A:$A,meta!$B$3,balance_sheet!$B:$B,"equity") -> 9887845 | F16: =D16-E16 -> 0 | G16: 0.001 | H16: =IF(ABS(F16)<=G16*ABS(E16),"PASS","FAIL") -> PASS
A17: 4 | B17: Income statement: NII = interest income - interest expense | C17: 2020-12-31 ytd | D17: =SUMIFS(income_statement!$E:$E,income_statement!$A:$A,"2020-12-31",income_statement!$B:$B,"ytd",income_statement!$C:$C,"interest_income")-SUMIFS(income_statement!$E:$E,income_statement!$A:$A,"2020-12-31",income_statement!$B:$B,"ytd",income_statement!$C:$C,"interest_expense") -> 132733.63 | E17: =income_statement_totals!$M$2 -> 132733.63 | F17: =D17-E17 -> 0 | G17: 0.5 | H17: =IF(ABS(F17)<=G17,"PASS","FAIL") -> PASS
A18: 4 | B18: Income statement: net income ties to components | C18: 2020-12-31 ytd | D18: =SUMIFS(income_statement!$E:$E,income_statement!$A:$A,"2020-12-31",income_statement!$B:$B,"ytd",income_statement!$C:$C,"interest_income")-SUMIFS(income_statement!$E:$E,income_statement!$A:$A,"2020-12-31",income_statement!$B:$B,"ytd",income_statement!$C:$C,"interest_expense")-SUMIFS(income_statement!$E:$E,income_statement!$A:$A,"2020-12-31",income_statement!$B:$B,"ytd",income_statement!$C:$C,"member_giveback")-SUMIFS(income_statement!$E:$E,income_statement!$A:$A,"2020-12-31",income_statement!$B:$B,"ytd",income_statement!$C:$C,"provision")+SUMIFS(income_statement!$E:$E,income_statement!$A:$A,"2020-12-31",income_statement!$B:$B,"ytd",income_statement!$C:$C,"noninterest_income")-SUMIFS(income_statement!$E:$E,income_statement!$A:$A,"2020-12-31",income_statement!$B:$B,"ytd",income_statement!$C:$C,"noninterest_expense")+SUMIFS(income_statement!$E:$E,income_statement!$A:$A,"2020-12-31",income_statement!$B:$B,"ytd",income_statement!$C:$C,"one_time") -> 42541.475 | E18: =income_statement_totals!$J$2 -> 42541.475 | F18: =D18-E18 -> 0 | G18: 0.5 | H18: =IF(ABS(F18)<=G18,"PASS","FAIL") -> PASS
A19: 4 | B19: Income statement: NII = interest income - interest expense | C19: 2021-12-31 ytd | D19: =SUMIFS(income_statement!$E:$E,income_statement!$A:$A,"2021-12-31",income_statement!$B:$B,"ytd",income_statement!$C:$C,"interest_income")-SUMIFS(income_statement!$E:$E,income_statement!$A:$A,"2021-12-31",income_statement!$B:$B,"ytd",income_statement!$C:$C,"interest_expense") -> 143032.57 | E19: =income_statement_totals!$M$3 -> 143032.57 | F19: =D19-E19 -> 0 | G19: 0.5 | H19: =IF(ABS(F19)<=G19,"PASS","FAIL") -> PASS
A20: 4 | B20: Income statement: net income ties to components | C20: 2021-12-31 ytd | D20: =SUMIFS(income_statement!$E:$E,income_statement!$A:$A,"2021-12-31",income_statement!$B:$B,"ytd",income_statement!$C:$C,"interest_income")-SUMIFS(income_statement!$E:$E,income_statement!$A:$A,"2021-12-31",income_statement!$B:$B,"ytd",income_statement!$C:$C,"interest_expense")-SUMIFS(income_statement!$E:$E,income_statement!$A:$A,"2021-12-31",income_statement!$B:$B,"ytd",income_statement!$C:$C,"member_giveback")-SUMIFS(income_statement!$E:$E,income_statement!$A:$A,"2021-12-31",income_statement!$B:$B,"ytd",income_statement!$C:$C,"provision")+SUMIFS(income_statement!$E:$E,income_statement!$A:$A,"2021-12-31",income_statement!$B:$B,"ytd",income_statement!$C:$C,"noninterest_income")-SUMIFS(income_statement!$E:$E,income_statement!$A:$A,"2021-12-31",income_statement!$B:$B,"ytd",income_statement!$C:$C,"noninterest_expense")+SUMIFS(income_statement!$E:$E,income_statement!$A:$A,"2021-12-31",income_statement!$B:$B,"ytd",income_statement!$C:$C,"one_time") -> 87441.822 | E20: =income_statement_totals!$J$3 -> 87441.822 | F20: =D20-E20 -> 0 | G20: 0.5 | H20: =IF(ABS(F20)<=G20,"PASS","FAIL") -> PASS
A21: 4 | B21: Income statement: NII = interest income - interest expense | C21: 2022-12-31 ytd | D21: =SUMIFS(income_statement!$E:$E,income_statement!$A:$A,"2022-12-31",income_statement!$B:$B,"ytd",income_statement!$C:$C,"interest_income")-SUMIFS(income_statement!$E:$E,income_statement!$A:$A,"2022-12-31",income_statement!$B:$B,"ytd",income_statement!$C:$C,"interest_expense") -> 198276.02 | E21: =income_statement_totals!$M$4 -> 198276.02 | F21: =D21-E21 -> 0 | G21: 0.5 | H21: =IF(ABS(F21)<=G21,"PASS","FAIL") -> PASS
A22: 4 | B22: Income statement: net income ties to components | C22: 2022-12-31 ytd | D22: =SUMIFS(income_statement!$E:$E,income_statement!$A:$A,"2022-12-31",income_statement!$B:$B,"ytd",income_statement!$C:$C,"interest_income")-SUMIFS(income_statement!$E:$E,income_statement!$A:$A,"2022-12-31",income_statement!$B:$B,"ytd",income_statement!$C:$C,"interest_expense")-SUMIFS(income_statement!$E:$E,income_statement!$A:$A,"2022-12-31",income_statement!$B:$B,"ytd",income_statement!$C:$C,"member_giveback")-SUMIFS(income_statement!$E:$E,income_statement!$A:$A,"2022-12-31",income_statement!$B:$B,"ytd",income_statement!$C:$C,"provision")+SUMIFS(income_statement!$E:$E,income_statement!$A:$A,"2022-12-31",income_statement!$B:$B,"ytd",income_statement!$C:$C,"noninterest_income")-SUMIFS(income_statement!$E:$E,income_statement!$A:$A,"2022-12-31",income_statement!$B:$B,"ytd",income_statement!$C:$C,"noninterest_expense")+SUMIFS(income_statement!$E:$E,income_statement!$A:$A,"2022-12-31",income_statement!$B:$B,"ytd",income_statement!$C:$C,"one_time") -> 86022.867 | E22: =income_statement_totals!$J$4 -> 86022.867 | F22: =D22-E22 -> 0 | G22: 0.5 | H22: =IF(ABS(F22)<=G22,"PASS","FAIL") -> PASS
A23: 4 | B23: Income statement: NII = interest income - interest expense | C23: 2023-12-31 ytd | D23: =SUMIFS(income_statement!$E:$E,income_statement!$A:$A,"2023-12-31",income_statement!$B:$B,"ytd",income_statement!$C:$C,"interest_income")-SUMIFS(income_statement!$E:$E,income_statement!$A:$A,"2023-12-31",income_statement!$B:$B,"ytd",income_statement!$C:$C,"interest_expense") -> 212420.64 | E23: =income_statement_totals!$M$5 -> 212420.64 | F23: =D23-E23 -> 0 | G23: 0.5 | H23: =IF(ABS(F23)<=G23,"PASS","FAIL") -> PASS
A24: 4 | B24: Income statement: net income ties to components | C24: 2023-12-31 ytd | D24: =SUMIFS(income_statement!$E:$E,income_statement!$A:$A,"2023-12-31",income_statement!$B:$B,"ytd",income_statement!$C:$C,"interest_income")-SUMIFS(income_statement!$E:$E,income_statement!$A:$A,"2023-12-31",income_statement!$B:$B,"ytd",income_statement!$C:$C,"interest_expense")-SUMIFS(income_statement!$E:$E,income_statement!$A:$A,"2023-12-31",income_statement!$B:$B,"ytd",income_statement!$C:$C,"member_giveback")-SUMIFS(income_statement!$E:$E,income_statement!$A:$A,"2023-12-31",income_statement!$B:$B,"ytd",income_statement!$C:$C,"provision")+SUMIFS(income_statement!$E:$E,income_statement!$A:$A,"2023-12-31",income_statement!$B:$B,"ytd",income_statement!$C:$C,"noninterest_income")-SUMIFS(income_statement!$E:$E,income_statement!$A:$A,"2023-12-31",income_statement!$B:$B,"ytd",income_statement!$C:$C,"noninterest_expense")+SUMIFS(income_statement!$E:$E,income_statement!$A:$A,"2023-12-31",income_statement!$B:$B,"ytd",income_statement!$C:$C,"one_time") -> 85294.418 | E24: =income_statement_totals!$J$5 -> 85294.418 | F24: =D24-E24 -> 0 | G24: 0.5 | H24: =IF(ABS(F24)<=G24,"PASS","FAIL") -> PASS
A25: 4 | B25: Income statement: NII = interest income - interest expense | C25: 2024-12-31 ytd | D25: =SUMIFS(income_statement!$E:$E,income_statement!$A:$A,"2024-12-31",income_statement!$B:$B,"ytd",income_statement!$C:$C,"interest_income")-SUMIFS(income_statement!$E:$E,income_statement!$A:$A,"2024-12-31",income_statement!$B:$B,"ytd",income_statement!$C:$C,"interest_expense") -> 217705.06 | E25: =income_statement_totals!$M$6 -> 217705.06 | F25: =D25-E25 -> 0 | G25: 0.5 | H25: =IF(ABS(F25)<=G25,"PASS","FAIL") -> PASS
A26: 4 | B26: Income statement: net income ties to components | C26: 2024-12-31 ytd | D26: =SUMIFS(income_statement!$E:$E,income_statement!$A:$A,"2024-12-31",income_statement!$B:$B,"ytd",income_statement!$C:$C,"interest_income")-SUMIFS(income_statement!$E:$E,income_statement!$A:$A,"2024-12-31",income_statement!$B:$B,"ytd",income_statement!$C:$C,"interest_expense")-SUMIFS(income_statement!$E:$E,income_statement!$A:$A,"2024-12-31",income_statement!$B:$B,"ytd",income_statement!$C:$C,"member_giveback")-SUMIFS(income_statement!$E:$E,income_statement!$A:$A,"2024-12-31",income_statement!$B:$B,"ytd",income_statement!$C:$C,"provision")+SUMIFS(income_statement!$E:$E,income_statement!$A:$A,"2024-12-31",income_statement!$B:$B,"ytd",income_statement!$C:$C,"noninterest_income")-SUMIFS(income_statement!$E:$E,income_statement!$A:$A,"2024-12-31",income_statement!$B:$B,"ytd",income_statement!$C:$C,"noninterest_expense")+SUMIFS(income_statement!$E:$E,income_statement!$A:$A,"2024-12-31",income_statement!$B:$B,"ytd",income_statement!$C:$C,"one_time") -> 72217.108 | E26: =income_statement_totals!$J$6 -> 72217.108 | F26: =D26-E26 -> 0 | G26: 0.5 | H26: =IF(ABS(F26)<=G26,"PASS","FAIL") -> PASS
A27: 4 | B27: Income statement: NII = interest income - interest expense | C27: 2025-12-31 ytd | D27: =SUMIFS(income_statement!$E:$E,income_statement!$A:$A,"2025-12-31",income_statement!$B:$B,"ytd",income_statement!$C:$C,"interest_income")-SUMIFS(income_statement!$E:$E,income_statement!$A:$A,"2025-12-31",income_statement!$B:$B,"ytd",income_statement!$C:$C,"interest_expense") -> 257443.59 | E27: =income_statement_totals!$M$7 -> 257443.59 | F27: =D27-E27 -> 0 | G27: 0.5 | H27: =IF(ABS(F27)<=G27,"PASS","FAIL") -> PASS
A28: 4 | B28: Income statement: net income ties to components | C28: 2025-12-31 ytd | D28: =SUMIFS(income_statement!$E:$E,income_statement!$A:$A,"2025-12-31",income_statement!$B:$B,"ytd",income_statement!$C:$C,"interest_income")-SUMIFS(income_statement!$E:$E,income_statement!$A:$A,"2025-12-31",income_statement!$B:$B,"ytd",income_statement!$C:$C,"interest_expense")-SUMIFS(income_statement!$E:$E,income_statement!$A:$A,"2025-12-31",income_statement!$B:$B,"ytd",income_statement!$C:$C,"member_giveback")-SUMIFS(income_statement!$E:$E,income_statement!$A:$A,"2025-12-31",income_statement!$B:$B,"ytd",income_statement!$C:$C,"provision")+SUMIFS(income_statement!$E:$E,income_statement!$A:$A,"2025-12-31",income_statement!$B:$B,"ytd",income_statement!$C:$C,"noninterest_income")-SUMIFS(income_statement!$E:$E,income_statement!$A:$A,"2025-12-31",income_statement!$B:$B,"ytd",income_statement!$C:$C,"noninterest_expense")+SUMIFS(income_statement!$E:$E,income_statement!$A:$A,"2025-12-31",income_statement!$B:$B,"ytd",income_statement!$C:$C,"one_time") -> 74570.244 | E28: =income_statement_totals!$J$7 -> 74570.244 | F28: =D28-E28 -> 0 | G28: 0.5 | H28: =IF(ABS(F28)<=G28,"PASS","FAIL") -> PASS
A29: 4 | B29: Income statement: NII = interest income - interest expense | C29: 2026-06-30 ytd | D29: =SUMIFS(income_statement!$E:$E,income_statement!$A:$A,"2026-06-30",income_statement!$B:$B,"ytd",income_statement!$C:$C,"interest_income")-SUMIFS(income_statement!$E:$E,income_statement!$A:$A,"2026-06-30",income_statement!$B:$B,"ytd",income_statement!$C:$C,"interest_expense") -> 155630.26 | E29: =income_statement_totals!$M$8 -> 155630.26 | F29: =D29-E29 -> 0 | G29: 0.5 | H29: =IF(ABS(F29)<=G29,"PASS","FAIL") -> PASS
A30: 4 | B30: Income statement: net income ties to components | C30: 2026-06-30 ytd | D30: =SUMIFS(income_statement!$E:$E,income_statement!$A:$A,"2026-06-30",income_statement!$B:$B,"ytd",income_statement!$C:$C,"interest_income")-SUMIFS(income_statement!$E:$E,income_statement!$A:$A,"2026-06-30",income_statement!$B:$B,"ytd",income_statement!$C:$C,"interest_expense")-SUMIFS(income_statement!$E:$E,income_statement!$A:$A,"2026-06-30",income_statement!$B:$B,"ytd",income_statement!$C:$C,"member_giveback")-SUMIFS(income_statement!$E:$E,income_statement!$A:$A,"2026-06-30",income_statement!$B:$B,"ytd",income_statement!$C:$C,"provision")+SUMIFS(income_statement!$E:$E,income_statement!$A:$A,"2026-06-30",income_statement!$B:$B,"ytd",income_statement!$C:$C,"noninterest_income")-SUMIFS(income_statement!$E:$E,income_statement!$A:$A,"2026-06-30",income_statement!$B:$B,"ytd",income_statement!$C:$C,"noninterest_expense")+SUMIFS(income_statement!$E:$E,income_statement!$A:$A,"2026-06-30",income_statement!$B:$B,"ytd",income_statement!$C:$C,"one_time") -> 54770.059 | E30: =income_statement_totals!$J$8 -> 54770.059 | F30: =D30-E30 -> 0 | G30: 0.5 | H30: =IF(ABS(F30)<=G30,"PASS","FAIL") -> PASS
A31: 4 | B31: Income statement: NII = interest income - interest expense | C31: 2025-03-31 qtd | D31: =SUMIFS(income_statement!$E:$E,income_statement!$A:$A,"2025-03-31",income_statement!$B:$B,"qtd",income_statement!$C:$C,"interest_income")-SUMIFS(income_statement!$E:$E,income_statement!$A:$A,"2025-03-31",income_statement!$B:$B,"qtd",income_statement!$C:$C,"interest_expense") -> 58939.936 | E31: =income_statement_totals!$M$9 -> 58939.936 | F31: =D31-E31 -> 0 | G31: 0.5 | H31: =IF(ABS(F31)<=G31,"PASS","FAIL") -> PASS
A32: 4 | B32: Income statement: net income ties to components | C32: 2025-03-31 qtd | D32: =SUMIFS(income_statement!$E:$E,income_statement!$A:$A,"2025-03-31",income_statement!$B:$B,"qtd",income_statement!$C:$C,"interest_income")-SUMIFS(income_statement!$E:$E,income_statement!$A:$A,"2025-03-31",income_statement!$B:$B,"qtd",income_statement!$C:$C,"interest_expense")-SUMIFS(income_statement!$E:$E,income_statement!$A:$A,"2025-03-31",income_statement!$B:$B,"qtd",income_statement!$C:$C,"member_giveback")-SUMIFS(income_statement!$E:$E,income_statement!$A:$A,"2025-03-31",income_statement!$B:$B,"qtd",income_statement!$C:$C,"provision")+SUMIFS(income_statement!$E:$E,income_statement!$A:$A,"2025-03-31",income_statement!$B:$B,"qtd",income_statement!$C:$C,"noninterest_income")-SUMIFS(income_statement!$E:$E,income_statement!$A:$A,"2025-03-31",income_statement!$B:$B,"qtd",income_statement!$C:$C,"noninterest_expense")+SUMIFS(income_statement!$E:$E,income_statement!$A:$A,"2025-03-31",income_statement!$B:$B,"qtd",income_statement!$C:$C,"one_time") -> 1683.1956 | E32: =income_statement_totals!$J$9 -> 1683.1956 | F32: =D32-E32 -> 0 | G32: 0.5 | H32: =IF(ABS(F32)<=G32,"PASS","FAIL") -> PASS
A33: 4 | B33: Income statement: NII = interest income - interest expense | C33: 2025-06-30 qtd | D33: =SUMIFS(income_statement!$E:$E,income_statement!$A:$A,"2025-06-30",income_statement!$B:$B,"qtd",income_statement!$C:$C,"interest_income")-SUMIFS(income_statement!$E:$E,income_statement!$A:$A,"2025-06-30",income_statement!$B:$B,"qtd",income_statement!$C:$C,"interest_expense") -> 62104.218 | E33: =income_statement_totals!$M$10 -> 62104.218 | F33: =D33-E33 -> 0 | G33: 0.5 | H33: =IF(ABS(F33)<=G33,"PASS","FAIL") -> PASS
A34: 4 | B34: Income statement: net income ties to components | C34: 2025-06-30 qtd | D34: =SUMIFS(income_statement!$E:$E,income_statement!$A:$A,"2025-06-30",income_statement!$B:$B,"qtd",income_statement!$C:$C,"interest_income")-SUMIFS(income_statement!$E:$E,income_statement!$A:$A,"2025-06-30",income_statement!$B:$B,"qtd",income_statement!$C:$C,"interest_expense")-SUMIFS(income_statement!$E:$E,income_statement!$A:$A,"2025-06-30",income_statement!$B:$B,"qtd",income_statement!$C:$C,"member_giveback")-SUMIFS(income_statement!$E:$E,income_statement!$A:$A,"2025-06-30",income_statement!$B:$B,"qtd",income_statement!$C:$C,"provision")+SUMIFS(income_statement!$E:$E,income_statement!$A:$A,"2025-06-30",income_statement!$B:$B,"qtd",income_statement!$C:$C,"noninterest_income")-SUMIFS(income_statement!$E:$E,income_statement!$A:$A,"2025-06-30",income_statement!$B:$B,"qtd",income_statement!$C:$C,"noninterest_expense")+SUMIFS(income_statement!$E:$E,income_statement!$A:$A,"2025-06-30",income_statement!$B:$B,"qtd",income_statement!$C:$C,"one_time") -> 23706.685 | E34: =income_statement_totals!$J$10 -> 23706.685 | F34: =D34-E34 -> 0 | G34: 0.5 | H34: =IF(ABS(F34)<=G34,"PASS","FAIL") -> PASS
A35: 4 | B35: Income statement: NII = interest income - interest expense | C35: 2025-09-30 qtd | D35: =SUMIFS(income_statement!$E:$E,income_statement!$A:$A,"2025-09-30",income_statement!$B:$B,"qtd",income_statement!$C:$C,"interest_income")-SUMIFS(income_statement!$E:$E,income_statement!$A:$A,"2025-09-30",income_statement!$B:$B,"qtd",income_statement!$C:$C,"interest_expense") -> 65969.013 | E35: =income_statement_totals!$M$11 -> 65969.013 | F35: =D35-E35 -> 0 | G35: 0.5 | H35: =IF(ABS(F35)<=G35,"PASS","FAIL") -> PASS
A36: 4 | B36: Income statement: net income ties to components | C36: 2025-09-30 qtd | D36: =SUMIFS(income_statement!$E:$E,income_statement!$A:$A,"2025-09-30",income_statement!$B:$B,"qtd",income_statement!$C:$C,"interest_income")-SUMIFS(income_statement!$E:$E,income_statement!$A:$A,"2025-09-30",income_statement!$B:$B,"qtd",income_statement!$C:$C,"interest_expense")-SUMIFS(income_statement!$E:$E,income_statement!$A:$A,"2025-09-30",income_statement!$B:$B,"qtd",income_statement!$C:$C,"member_giveback")-SUMIFS(income_statement!$E:$E,income_statement!$A:$A,"2025-09-30",income_statement!$B:$B,"qtd",income_statement!$C:$C,"provision")+SUMIFS(income_statement!$E:$E,income_statement!$A:$A,"2025-09-30",income_statement!$B:$B,"qtd",income_statement!$C:$C,"noninterest_income")-SUMIFS(income_statement!$E:$E,income_statement!$A:$A,"2025-09-30",income_statement!$B:$B,"qtd",income_statement!$C:$C,"noninterest_expense")+SUMIFS(income_statement!$E:$E,income_statement!$A:$A,"2025-09-30",income_statement!$B:$B,"qtd",income_statement!$C:$C,"one_time") -> 22458.245 | E36: =income_statement_totals!$J$11 -> 22458.245 | F36: =D36-E36 -> 0 | G36: 0.5 | H36: =IF(ABS(F36)<=G36,"PASS","FAIL") -> PASS
A37: 4 | B37: Income statement: NII = interest income - interest expense | C37: 2025-12-31 qtd | D37: =SUMIFS(income_statement!$E:$E,income_statement!$A:$A,"2025-12-31",income_statement!$B:$B,"qtd",income_statement!$C:$C,"interest_income")-SUMIFS(income_statement!$E:$E,income_statement!$A:$A,"2025-12-31",income_statement!$B:$B,"qtd",income_statement!$C:$C,"interest_expense") -> 70430.426 | E37: =income_statement_totals!$M$12 -> 70430.426 | F37: =D37-E37 -> 0 | G37: 0.5 | H37: =IF(ABS(F37)<=G37,"PASS","FAIL") -> PASS
A38: 4 | B38: Income statement: net income ties to components | C38: 2025-12-31 qtd | D38: =SUMIFS(income_statement!$E:$E,income_statement!$A:$A,"2025-12-31",income_statement!$B:$B,"qtd",income_statement!$C:$C,"interest_income")-SUMIFS(income_statement!$E:$E,income_statement!$A:$A,"2025-12-31",income_statement!$B:$B,"qtd",income_statement!$C:$C,"interest_expense")-SUMIFS(income_statement!$E:$E,income_statement!$A:$A,"2025-12-31",income_statement!$B:$B,"qtd",income_statement!$C:$C,"member_giveback")-SUMIFS(income_statement!$E:$E,income_statement!$A:$A,"2025-12-31",income_statement!$B:$B,"qtd",income_statement!$C:$C,"provision")+SUMIFS(income_statement!$E:$E,income_statement!$A:$A,"2025-12-31",income_statement!$B:$B,"qtd",income_statement!$C:$C,"noninterest_income")-SUMIFS(income_statement!$E:$E,income_statement!$A:$A,"2025-12-31",income_statement!$B:$B,"qtd",income_statement!$C:$C,"noninterest_expense")+SUMIFS(income_statement!$E:$E,income_statement!$A:$A,"2025-12-31",income_statement!$B:$B,"qtd",income_statement!$C:$C,"one_time") -> 26722.118 | E38: =income_statement_totals!$J$12 -> 26722.118 | F38: =D38-E38 -> 0 | G38: 0.5 | H38: =IF(ABS(F38)<=G38,"PASS","FAIL") -> PASS
A39: 4 | B39: Income statement: NII = interest income - interest expense | C39: 2026-03-31 qtd | D39: =SUMIFS(income_statement!$E:$E,income_statement!$A:$A,"2026-03-31",income_statement!$B:$B,"qtd",income_statement!$C:$C,"interest_income")-SUMIFS(income_statement!$E:$E,income_statement!$A:$A,"2026-03-31",income_statement!$B:$B,"qtd",income_statement!$C:$C,"interest_expense") -> 77032.458 | E39: =income_statement_totals!$M$13 -> 77032.458 | F39: =D39-E39 -> 0 | G39: 0.5 | H39: =IF(ABS(F39)<=G39,"PASS","FAIL") -> PASS
A40: 4 | B40: Income statement: net income ties to components | C40: 2026-03-31 qtd | D40: =SUMIFS(income_statement!$E:$E,income_statement!$A:$A,"2026-03-31",income_statement!$B:$B,"qtd",income_statement!$C:$C,"interest_income")-SUMIFS(income_statement!$E:$E,income_statement!$A:$A,"2026-03-31",income_statement!$B:$B,"qtd",income_statement!$C:$C,"interest_expense")-SUMIFS(income_statement!$E:$E,income_statement!$A:$A,"2026-03-31",income_statement!$B:$B,"qtd",income_statement!$C:$C,"member_giveback")-SUMIFS(income_statement!$E:$E,income_statement!$A:$A,"2026-03-31",income_statement!$B:$B,"qtd",income_statement!$C:$C,"provision")+SUMIFS(income_statement!$E:$E,income_statement!$A:$A,"2026-03-31",income_statement!$B:$B,"qtd",income_statement!$C:$C,"noninterest_income")-SUMIFS(income_statement!$E:$E,income_statement!$A:$A,"2026-03-31",income_statement!$B:$B,"qtd",income_statement!$C:$C,"noninterest_expense")+SUMIFS(income_statement!$E:$E,income_statement!$A:$A,"2026-03-31",income_statement!$B:$B,"qtd",income_statement!$C:$C,"one_time") -> 21206.147 | E40: =income_statement_totals!$J$13 -> 21206.147 | F40: =D40-E40 -> 0 | G40: 0.5 | H40: =IF(ABS(F40)<=G40,"PASS","FAIL") -> PASS
A41: 4 | B41: Income statement: NII = interest income - interest expense | C41: 2026-03-31 ytd | D41: =SUMIFS(income_statement!$E:$E,income_statement!$A:$A,"2026-03-31",income_statement!$B:$B,"ytd",income_statement!$C:$C,"interest_income")-SUMIFS(income_statement!$E:$E,income_statement!$A:$A,"2026-03-31",income_statement!$B:$B,"ytd",income_statement!$C:$C,"interest_expense") -> 77032.458 | E41: =income_statement_totals!$M$14 -> 77032.458 | F41: =D41-E41 -> 0 | G41: 0.5 | H41: =IF(ABS(F41)<=G41,"PASS","FAIL") -> PASS
...

Sheet meta
A1: key | B1: value | C1: description
A2: institution | B2: Desert Financial Credit Union (hypothetical concept; NCUA charter 68713) | C2: Subject institution. Hypothetical concept built from public data.
A3: as_of_date | B3: 2026-06-30 | C3: Balance sheet and model as-of date (latest call report)
A4: units | B4: USD thousands | C4: All dollar amounts are in thousands; rates and ratios are decimals
A5: nwr_method | B5: four_quarter_average | C5: Net worth / average of the current and three prior quarter-end total assets (matches reported 12.1% at June 30, 2026)
A6: capital_target_nwr | B6: 0.11 | C6: Board capital target (hypothetical)
A7: watch_pct_default | B7: 0.75 | C7: Utilization at which a maximum or max-decline limit turns Watch
A8: min_watch_buffer | B8: 0.1 | C8: A minimum limit turns Watch within this fraction above the minimum
A9: peer_group | B9: cu_5b_20b | C9: Default peer set in peers (hypothetical placeholder values)
A10: disclaimer | B10: Hypothetical concept built from public data. Not affiliated with or endorsed by Desert Financial Credit Union. | C10: Show on every page and export
A11: model_version | B11: DFCU ALM model v1.0 (built 2026-09-30) | C11: Python model in model/ (run build_all.py)
A12: data_cutoff | B12: 2026-09-29 | C12: Latest market data used (Treasury curve Sept 29, 2026)
A13: rate_drift_curve_date | B13: 2026-09-29 | C13: Curve newer than the as-of date (drives the rate-drift chip)
A14: cculr_elected | B14: y | C14: Complex credit union leverage ratio elected (CreditUnionsOnline)
A15: cculr_threshold | B15: 0.09 | C15: CCULR well-capitalized net worth ratio
A16: well_capitalized_nwr | B16: 0.07 | C16: Statutory well-capitalized NWR used in the MBL cap
A17: mbl_multiple | B17: 1.75 | C17: MBL cap multiple (12 CFR 723.8)
A18: nev_test_low_ratio | B18: 0.07 | C18: NEV Test: Low requires post-shock NEV ratio above 7%
A19: nev_test_high_ratio | B19: 0.04 | C19: NEV Test: High if post-shock NEV ratio below 4%
A20: nev_test_low_sensitivity | B20: 0.4 | C20: NEV Test: Low requires NEV decline under 40%
A21: nev_test_high_sensitivity | B21: 0.65 | C21: NEV Test: High if NEV decline exceeds 65%
A22: threshold_10b | B22: 10000000 | C22: Asset threshold for capital planning, Durbin coverage and CFPB ($K)
A23: nii_definition | B23: excludes Member Giveback Bonus | C23: NII = interest income - interest expense; the giveback is reported within dividends by DFCU but is its own category here
A24: giveback_recognition | B24: Q1 dividends when paid (inferred) | C24: See notes: consistent with the Q1 2026 earnings dip and dividend-cost dynamics
A25: scenario_start | B25: 2026-07-01 | C25: Month 1 of every scenario is July 2026
A26: fiscal_year_end | B26: 12-31 | C26: Calendar fiscal year

Sheet balance_sheet
A1: period | B1: section | C1: category | D1: line_item | E1: balance | F1: avg_balance | G1: rate | H1: rate_type | I1: index | J1: wal_years | K1: eff_duration | L1: eff_convexity | M1: provenance | N1: source | O1: line_key | P1: amortized_cost | Q1: fair_value_base
A2: 2020-12-31 | B2: asset | C2: cash | D2: Cash and cash equivalents | E2: 558933.19 | H2: none | I2: sofr | M2: audited | N2: Desert Financial 2021 Annual Report (audited FY2020)
A3: 2020-12-31 | B3: asset | C3: investments | D3: Equity securities | E3: 114014.09 | H3: none | I3: none | M3: audited | N3: Desert Financial 2021 Annual Report (audited FY2020)
A4: 2020-12-31 | B4: asset | C4: investments | D4: Securities available for sale (fair value) | E4: 1893344.8 | H4: none | I4: none | M4: audited | N4: Desert Financial 2021 Annual Report (audited FY2020)
A5: 2020-12-31 | B5: asset | C5: investments | D5: Securities held to maturity (amortized cost) | E5: 1447713.2 | H5: none | I5: none | M5: audited | N5: Desert Financial 2021 Annual Report (audited FY2020)
A6: 2020-12-31 | B6: asset | C6: investments | D6: FHLB stock | E6: 17250 | H6: none | I6: none | M6: audited | N6: Desert Financial 2021 Annual Report (audited FY2020)
A7: 2020-12-31 | B7: asset | C7: loans_hfs | D7: Loans held for sale | E7: 6015.74 | H7: none | I7: none | M7: audited | N7: Desert Financial 2021 Annual Report (audited FY2020)
A8: 2020-12-31 | B8: asset | C8: loans | D8: Loans, net of allowance for credit losses | E8: 2333705 | H8: fixed | I8: none | M8: audited | N8: Desert Financial 2021 Annual Report (audited FY2020)
A9: 2020-12-31 | B9: asset | C9: other_assets | D9: Accrued interest receivable | E9: 19853.458 | H9: none | I9: none | M9: audited | N9: Desert Financial 2021 Annual Report (audited FY2020)
A10: 2020-12-31 | B10: asset | C10: other_assets | D10: Prepaid expenses and other assets | E10: 43100.662 | H10: none | I10: none | M10: audited | N10: Desert Financial 2021 Annual Report (audited FY2020)
A11: 2020-12-31 | B11: asset | C11: other_assets | D11: Credit union-owned life insurance | E11: 74359.306 | H11: none | I11: none | M11: audited | N11: Desert Financial 2021 Annual Report (audited FY2020)
A12: 2020-12-31 | B12: asset | C12: other_assets | D12: Mortgage servicing rights | E12: 9131.968 | H12: none | I12: none | M12: audited | N12: Desert Financial 2021 Annual Report (audited FY2020)
A13: 2020-12-31 | B13: asset | C13: other_assets | D13: Premises and equipment, net | E13: 72862.061 | H13: none | I13: none | M13: audited | N13: Desert Financial 2021 Annual Report (audited FY2020)
... A20: 2020-12-31 | B20: equity | C20: equity | D20: Accumulated other comprehensive income (loss) | E20: 39342.022 | H20: none | I20: none | M20: audited | N20: Desert Financial 2021 Annual Report (audited FY2020)
A21: 2021-12-31 | B21: asset | C21: cash | D21: Cash and cash equivalents | E21: 601184.08 | F21: 580058.64 | H21: none | I21: sofr | M21: audited | N21: Desert Financial 2021 Annual Report (audited FY2021)
A22: 2021-12-31 | B22: asset | C22: investments | D22: Equity securities | E22: 1348.898 | F22: 57681.494 | H22: none | I22: none | M22: audited | N22: Desert Financial 2021 Annual Report (audited FY2021)
A23: 2021-12-31 | B23: asset | C23: investments | D23: Securities available for sale (fair value) | E23: 2791744.8 | F23: 2342544.8 | H23: none | I23: none | M23: audited | N23: Desert Financial 2021 Annual Report (audited FY2021)
A24: 2021-12-31 | B24: asset | C24: investments | D24: Securities held to maturity (amortized cost) | E24: 1684913.3 | F24: 1566313.2 | H24: none | I24: none | M24: audited | N24: Desert Financial 2021 Annual Report (audited FY2021)
A25: 2021-12-31 | B25: asset | C25: investments | D25: FHLB stock | E25: 17250 | F25: 17250 | H25: none | I25: none | M25: audited | N25: Desert Financial 2021 Annual Report (audited FY2021)
A26: 2021-12-31 | B26: asset | C26: loans_hfs | D26: Loans held for sale | E26: 4679.303 | F26: 5347.5215 | H26: none | I26: none | M26: audited | N26: Desert Financial 2021 Annual Report (audited FY2021)
A27: 2021-12-31 | B27: asset | C27: loans | D27: Loans, net of allowance for credit losses | E27: 2701948.3 | F27: 2517826.7 | G27: 0.037633095 | H27: fixed | I27: none | M27: audited | N27: Desert Financial 2021 Annual Report (audited FY2021)
A28: 2021-12-31 | B28: asset | C28: other_assets | D28: Accrued interest receivable | E28: 20506.772 | F28: 20180.115 | H28: none | I28: none | M28: audited | N28: Desert Financial 2021 Annual Report (audited FY2021)
A29: 2021-12-31 | B29: asset | C29: other_assets | D29: Prepaid expenses and other assets | E29: 62288.362 | F29: 52694.512 | H29: none | I29: none | M29: audited | N29: Desert Financial 2021 Annual Report (audited FY2021)
A30: 2021-12-31 | B30: asset | C30: other_assets | D30: Visa class B stock | E30: 42447.963 | F30: 21223.982 | H30: none | I30: none | M30: audited | N30: Desert Financial 2021 Annual Report (audited FY2021)
A31: 2021-12-31 | B31: asset | C31: other_assets | D31: Credit union-owned life insurance | E31: 134148.9 | F31: 104254.1 | H31: none | I31: none | M31: audited | N31: Desert Financial 2021 Annual Report (audited FY2021)
A32: 2021-12-31 | B32: asset | C32: other_assets | D32: Mortgage servicing rights | E32: 11573.593 | F32: 10352.781 | H32: none | I32: none | M32: audited | N32: Desert Financial 2021 Annual Report (audited FY2021)
A33: 2021-12-31 | B33: asset | C33: other_assets | D33: Premises and equipment, net | E33: 71768.086 | F33: 72315.073 | H33: none | I33: none | M33: audited | N33: Desert Financial 2021 Annual Report (audited FY2021)
A34: 2021-12-31 | B34: asset | C34: other_assets | D34: NCUSIF deposit | E34: 60571.032 | F34: 54118.654 | H34: none | I34: none | M34: audited | N34: Desert Financial 2021 Annual Report (audited FY2021)
A35: 2021-12-31 | B35: liability | C35: shares | D35: Members' shares and savings accounts | E35: 7140002 | F35: 6369503.9 | G35: 0.0025495468 | H35: variable | I35: none | M35: audited | N35: Desert Financial 2021 Annual Report (audited FY2021)
A36: 2021-12-31 | B36: liability | C36: borrowings | D36: Borrowed funds | E36: 200000 | F36: 202500 | G36: 0.019921121 | H36: fixed | I36: none | M36: audited | N36: Desert Financial 2021 Annual Report (audited FY2021)
A37: 2021-12-31 | B37: liability | C37: other_liabilities | D37: Accrued expenses and other liabilities | E37: 94329.952 | F37: 84210.221 | H37: none | I37: none | M37: audited | N37: Desert Financial 2021 Annual Report (audited FY2021)
A38: 2021-12-31 | B38: equity | C38: equity | D38: Regular reserve | E38: 29788.065 | F38: 29788.065 | H38: none | I38: none | M38: audited | N38: Desert Financial 2021 Annual Report (audited FY2021)
A39: 2021-12-31 | B39: equity | C39: equity | D39: Undivided earnings | E39: 778165.22 | F39: 734444.31 | H39: none | I39: none | M39: audited | N39: Desert Financial 2021 Annual Report (audited FY2021)
A40: 2021-12-31 | B40: equity | C40: equity | D40: Accumulated other comprehensive income (loss) | E40: -35911.86 | F40: 1715.081 | H40: none | I40: none | M40: audited | N40: Desert Financial 2021 Annual Report (audited FY2021)
A41: 2022-12-31 | B41: asset | C41: cash | D41: Cash and cash equivalents | E41: 196813.41 | F41: 398998.75 | H41: none | I41: sofr | M41: audited | N41: Desert Financial 2023 Annual Report (audited FY2022)
A42: 2022-12-31 | B42: asset | C42: investments | D42: Equity securities | E42: 1561.391 | F42: 1455.1445 | H42: none | I42: none | M42: audited | N42: Desert Financial 2023 Annual Report (audited FY2022)
A43: 2022-12-31 | B43: asset | C43: investments | D43: Securities available for sale (fair value) | E43: 2190628.8 | F43: 2491186.8 | H43: none | I43: none | M43: audited | N43: Desert Financial 2023 Annual Report (audited FY2022)
